<?xml version="1.0"?>
<robot xmlns:xacro="http://ros.org/wiki/xacro">
	<xacro:include filename="$(find mir_description)/urdf/general/common_properties.urdf.xacro" />

	<xacro:macro name="top_module" params="">
		
		<!-- top module -->
		<link name="top_module">
			<xacro:box_inertial mass="${mir_600_top_module_mass}" x="1.35" y="0.91" z="0.5">
				<origin xyz="${mir_600_act_wheel_dx} 0 0.25" rpy="0 0 0" />
			</xacro:box_inertial>
			<visual>
				<origin xyz="${mir_600_act_wheel_dx} 0 0" rpy="${pi * 0.5} 0 ${pi * 0.5}" />
				<geometry>
					<mesh filename="package://mir_description/meshes/visual/mir_600_top_module.stl"/>
				</geometry>
				<xacro:insert_block name="material_white" />
			</visual>
			<collision>
				<origin xyz="${mir_600_act_wheel_dx} 0 0" rpy="${pi * 0.5} 0 ${pi * 0.5}" />
				<geometry>
					<mesh filename="package://mir_description/meshes/collision/mir_600_top_module.stl"/>
				</geometry>
			</collision>
		</link>

		<joint name="top_module_joint" type="fixed">
			<origin xyz="0 0 0.832" rpy="0 0 0" />
			<parent link="base_link" />
			<child link="top_module" />
			<axis xyz="0 0 1" />
		</joint>

		<link name="left_lift_bottom">
			<xacro:box_inertial mass="${mir_600_lift_mass}" x="0.2" y="0.2" z="0.3">
				<origin xyz="0 0 0.15" rpy="0 0 0" />
			</xacro:box_inertial>
			<visual>
				<origin xyz="0 0 0" rpy="${pi * 0.5} 0 ${pi * 0.0}" />
				<geometry>
					<mesh filename="package://mir_description/meshes/visual/mir_600_lift_bot.stl"/>
				</geometry>
				<xacro:insert_block name="material_white" />
			</visual>
			<collision>
				<origin xyz="0 0 0" rpy="${pi * 0.5} 0 ${pi * 0.0}" />
				<geometry>
					<mesh filename="package://mir_description/meshes/collision/mir_600_lift_bot.stl"/>
				</geometry>
			</collision>
		</link>

		<joint name="left_lift_bottom_joint" type="fixed">
			<origin xyz="0.549 0.318 -0.49" rpy="0 0 0" />
			<parent link="top_module" />
			<child link="left_lift_bottom" />
			<axis xyz="0 0 1" />
		</joint>

		<link name="left_lift_top">
			<xacro:box_inertial mass="1.0" x="0.2" y="0.2" z="0.3">
				<origin xyz="0 0 0.15" rpy="0 0 0" />
			</xacro:box_inertial>
			<visual>
				<origin xyz="0 0 0" rpy="${pi * 0.5} 0 ${pi * 0.0}" />
				<geometry>
					<mesh filename="package://mir_description/meshes/visual/mir_600_lift_top.stl"/>
				</geometry>
				<xacro:insert_block name="material_white" />
			</visual>
			<collision>
				<origin xyz="0 0 0" rpy="${pi * 0.5} 0 ${pi * 0.0}" />
				<geometry>
					<mesh filename="package://mir_description/meshes/collision/mir_600_lift_top.stl"/>
				</geometry>
			</collision>
		</link>

		<joint name="left_lift_joint" type="prismatic">
			<origin xyz="0.0 0.0 0.0" rpy="0 0 0" />
			<parent link="left_lift_bottom" />
			<child link="left_lift_top" />
			<dynamics damping="1.0" friction="1.0"/>
			<limit lower="0.0" upper="0.5" effort="1000000" velocity="1.0"/>
			<axis xyz="0 0 1" />
		</joint>

		<link name="right_lift_bottom">
			<xacro:box_inertial mass="${mir_600_lift_mass}" x="0.2" y="0.2" z="0.3">
				<origin xyz="0 0 0.15" rpy="0 0 0" />
			</xacro:box_inertial>
			<visual>
				<origin xyz="0 0 0" rpy="${pi * 0.5} 0 ${pi * 0.0}" />
				<geometry>
					<mesh filename="package://mir_description/meshes/visual/mir_600_lift_bot.stl"/>
				</geometry>
				<xacro:insert_block name="material_white" />
			</visual>
			<collision>
				<origin xyz="0 0 0" rpy="${pi * 0.5} 0 ${pi * 0.0}" />
				<geometry>
					<mesh filename="package://mir_description/meshes/collision/mir_600_lift_bot.stl"/>
				</geometry>
			</collision>
		</link>

		<joint name="right_lift_bottom_joint" type="fixed">
			<origin xyz="0.549 -0.318 -0.49" rpy="0 0 0" />
			<parent link="top_module" />
			<child link="right_lift_bottom" />
			<axis xyz="0 0 1" />
		</joint>

		<link name="right_lift_top">
			<xacro:box_inertial mass="1.0" x="0.2" y="0.2" z="0.3">
				<origin xyz="0 0 0.15" rpy="0 0 0" />
			</xacro:box_inertial>
			<visual>
				<origin xyz="0 0 0" rpy="${pi * 0.5} 0 ${pi * 0.0}" />
				<geometry>
					<mesh filename="package://mir_description/meshes/visual/mir_600_lift_top.stl"/>
				</geometry>
				<xacro:insert_block name="material_white" />
			</visual>
			<collision>
				<origin xyz="0 0 0" rpy="${pi * 0.5} 0 ${pi * 0.0}" />
				<geometry>
					<mesh filename="package://mir_description/meshes/collision/mir_600_lift_top.stl"/>
				</geometry>
			</collision>
		</link>

		<joint name="right_lift_joint" type="prismatic">
			<origin xyz="0.0 0.0 0.0" rpy="0 0 0" />
			<parent link="right_lift_bottom" />
			<child link="right_lift_top" />
			<dynamics damping="1.0" friction="1.0"/>
			<limit lower="0.0" upper="0.5" effort="1000000" velocity="1.0"/>
			<axis xyz="0 0 1" />
		</joint>

		<transmission name="left_lift_transmission">
			<type>transmission_interface/SimpleTransmission</type>
			<joint name="left_lift_joint">
			  <hardwareInterface>hardware_interface/VelocityJointInterface</hardwareInterface>
			</joint>
			<actuator name="left_lift_joint_motor">
			  <hardwareInterface>hardware_interface/VelocityJointInterface</hardwareInterface>
			  <mechanicalReduction>1</mechanicalReduction>
			</actuator>
		</transmission>

		<transmission name="right_lift_transmission">
			<type>transmission_interface/SimpleTransmission</type>
			<joint name="right_lift_joint">
			  <hardwareInterface>hardware_interface/VelocityJointInterface</hardwareInterface>
			</joint>
			<actuator name="right_lift_joint_motor">
			  <hardwareInterface>hardware_interface/VelocityJointInterface</hardwareInterface>
			  <mechanicalReduction>1</mechanicalReduction>
			</actuator>
		</transmission>

		
	</xacro:macro>


</robot>