<?xml version="1.0"?>
<robot xmlns:xacro="http://ros.org/wiki/xacro">

	<xacro:macro name="actuated_wheel" params="locationprefix locationright">
		<joint name="${locationprefix}_wheel_joint" type="continuous">
		<origin xyz="0.0 ${-mir_100_act_wheel_dy * locationright} ${mir_100_act_wheel_radius}" rpy="0 0 0" />
		<parent link="base_link" />
		<child link="${locationprefix}_wheel_link" />
		<axis xyz="0 1 0" />
		<limit effort="100" velocity="20.0" />
		</joint>

		<link name="${locationprefix}_wheel_link">
		<xacro:cylinder_inertial mass="${mir_100_act_wheel_mass}" radius="${mir_100_act_wheel_radius}" length="${mir_100_act_wheel_width}">
			<origin xyz="0 0 0" rpy="${0.5 * pi} 0 0" />
		</xacro:cylinder_inertial>
		<visual>
			<origin xyz="0 0 0" rpy="0 0 0" />
			<geometry>
			<mesh filename="package://mir_description/meshes/visual/wheel.stl" />
			</geometry>
			<xacro:insert_block name="material_dark_grey" />
		</visual>
		<collision>
			<origin xyz="0 0 0" rpy="0 0 0" />
			<geometry>
			<mesh filename="package://mir_description/meshes/visual/wheel.stl" />
			</geometry>
		</collision>
		</link>
		<gazebo reference="${locationprefix}_wheel_link">
		<material>Gazebo/DarkGrey</material>
		</gazebo>
	</xacro:macro>

	<xacro:macro name="caster_wheel" params="locationprefix locationright wheel_base_dx">
		<!-- caster hub -->
		<joint name="${locationprefix}_caster_rotation_joint" type="continuous">
		<origin xyz="${wheel_base_dx} ${-mir_100_caster_wheel_base_dy * locationright} ${mir_100_caster_wheel_base_dz}" rpy="0 0 0" />
		<parent link="base_link" />
		<child link="${locationprefix}_caster_rotation_link" />
		<axis xyz="0 0 1" />
		<dynamics damping="0.01" friction="0.0"/>
		</joint>

		<link name="${locationprefix}_caster_rotation_link">
		<inertial>
			<!-- <origin xyz="0 0 -0.042500000044" rpy="${0.5 * pi} ${24 * deg_to_rad} ${1.5 * pi}" /> -->
			<origin xyz="0 0 -0.042500000044" rpy="${24 * deg_to_rad} 0 ${0.5 * pi} " />
			<mass value="0.3097539019" />
			<inertia
			ixx="0.0005844517978"
			ixy="0"
			ixz="0"
			iyy="0.00052872551237"
			iyz="0"
			izz="0.00017923555074" />
		</inertial>
		<visual>
			<origin xyz="0 0 0" rpy="0 0 0" />
			<geometry>
			<mesh filename="package://mir_description/meshes/visual/caster_wheel_base.stl" />
			</geometry>
			<xacro:insert_block name="material_silver" />
		</visual>
		<collision>
			<origin xyz="0 0 0" rpy="0 0 0" />
			<geometry>
			<mesh filename="package://mir_description/meshes/collision/caster_wheel_base.stl" />
			</geometry>
		</collision>
		</link>
		<gazebo reference="${locationprefix}_caster_rotation_link">
		<material>Gazebo/Grey</material>
		</gazebo>

		<!-- caster wheel -->
		<joint name="${locationprefix}_caster_wheel_joint" type="continuous">
		<origin xyz="${mir_100_caster_wheel_dx} ${-mir_100_caster_wheel_dy * locationright} ${mir_100_caster_wheel_dz}" rpy="0 0 0" />
		<parent link="${locationprefix}_caster_rotation_link" />
		<child link="${locationprefix}_caster_wheel_link" />
		<axis xyz="0 1 0" />
		</joint>

		<link name="${locationprefix}_caster_wheel_link">
		<xacro:cylinder_inertial mass="${mir_100_caster_wheel_mass}" radius="${mir_100_caster_wheel_radius}" length="${mir_100_caster_wheel_width}">
			<origin xyz="0 0 0" rpy="${0.5 * pi} 0 0" />
		</xacro:cylinder_inertial>
		<visual>
			<origin xyz="0 0 0" rpy="0 0 0" />
			<geometry>
			<mesh filename="package://mir_description/meshes/visual/wheel.stl" />
			</geometry>
			<xacro:insert_block name="material_dark_grey" />
		</visual>
		<collision>
			<origin xyz="0 0 0" rpy="0 0 0" />
			<geometry>
			<mesh filename="package://mir_description/meshes/visual/wheel.stl" />
			</geometry>
		</collision>
		</link>
		<gazebo reference="${locationprefix}_caster_wheel_link">
		<material>Gazebo/DarkGrey</material>
		</gazebo>
	</xacro:macro>

	<xacro:macro name="mir_100_wheel_transmission" params="locationprefix">
		<transmission name="${locationprefix}_wheel_trans">
			<type>transmission_interface/SimpleTransmission</type>
			<joint name="${locationprefix}_wheel_joint">
				<hardwareInterface>hardware_interface/VelocityJointInterface</hardwareInterface>
			</joint>
			<actuator name="${locationprefix}_wheel_motor">
				<hardwareInterface>hardware_interface/VelocityJointInterface</hardwareInterface>
				<mechanicalReduction>1</mechanicalReduction>
			</actuator>
		</transmission>
	</xacro:macro>

	<xacro:macro name="mir_100_wheel_transmissions">
		<xacro:mir_100_wheel_transmission locationprefix="left"/>
		<xacro:mir_100_wheel_transmission locationprefix="right"/>
	</xacro:macro>
</robot>
